<?xml version="1.0"?>
<robot xmlns:xacro="http://www.ros.org/wiki/xacro">

  <!-- Define constants -->
  <xacro:property name="M_PI" value="0"/>
  <xacro:property name="wheel_scale" value="1.5 1.5 1.5"/>

  <!-- Inertial Macros -->
  <xacro:macro name="inertial_box" params="mass x y z">
    <inertial>
      <origin xyz="${x/2} ${y/2} ${z/2}" rpy="0 0 0"/>
      <mass value="${mass}"/>
      <inertia ixx="${mass*(y*y + z*z)/12}" 
               ixy="0" 
               ixz="0"
               iyy="${mass*(x*x + z*z)/12}" 
               iyz="0"
               izz="${mass*(x*x + y*y)/12}"/>
    </inertial>
  </xacro:macro>

  <xacro:macro name="inertial_cylinder" params="mass radius length">
    <inertial>
      <origin xyz="0 0 0" rpy="0 0 0"/>
      <mass value="${mass}"/>
      <inertia ixx="${mass*(3*radius*radius + length*length)/12}"
               ixy="0"
               ixz="0"
               iyy="${mass*(3*radius*radius + length*length)/12}"
               iyz="0"
               izz="${mass*(radius*radius)/2}"/>
    </inertial>
  </xacro:macro>

  <!-- Robot Core Macro -->
  <xacro:macro name="robot_core" params="base_mesh wheel_mesh_path">
    <!-- Base Link -->
    <link name="base_link">
      <visual>
        <origin xyz="0 0 -0.15" rpy="0 0 0"/>
        <geometry>
          <mesh filename="${base_mesh}"/>
        </geometry>
        <material name="Orange">
          <color rgba="1.0 0.5 0.0 1.0"/>
        </material>
      </visual>
      <collision>
        <origin xyz="0 0 -0.15" rpy="0 0 0"/>
        <geometry>
          <mesh filename="${base_mesh}"/>
        </geometry>
      </collision>
      <xacro:inertial_box mass="30" x="0.22" y="0.32" z="0.22"/>
      <gazebo>
        <mu1>1.0</mu1>
        <mu2>1.0</mu2>
        <kp>100000</kp>
        <kd>1.0</kd>
      </gazebo>
    </link>

    <!-- Base Footprint -->
    <link name="base_footprint"/>
    <joint name="base_joint" type="fixed">
      <parent link="base_link"/>
      <child link="base_footprint"/>
      <origin rpy="0 0 0" xyz="0.0 0.0 0.0"/>
      <dynamics damping="0.05"/>
    </joint>

    <!-- Wheels -->
    <xacro:wheel name="fr" parent="base_link" xyz="0.45 -0.23 0.185" mesh="${wheel_mesh_path}/fr_wheel.dae"/>
    <xacro:wheel name="fl" parent="base_link" xyz="0.45 0.47 0.185" mesh="${wheel_mesh_path}/fl_wheel.dae"/>
    <xacro:wheel name="rl" parent="base_link" xyz="-0.2 0.47 0.185" mesh="${wheel_mesh_path}/fl_wheel.dae"/>
    <xacro:wheel name="rr" parent="base_link" xyz="-0.2 -0.23 0.185" mesh="${wheel_mesh_path}/fr_wheel.dae"/>
  </xacro:macro>

  <!-- Wheel Macro -->
  <xacro:macro name="wheel" params="name parent xyz mesh">
    <link name="${name}_link">
      <visual>
        <origin xyz="0 0 0" rpy="${M_PI/2} 0 0"/>
        <geometry>
          <mesh filename="${mesh}" scale="${wheel_scale}"/>
        </geometry>
        <material name="DarkGray">
          <color rgba="0.1 0.1 0.1 1.0"/>
        </material>
      </visual>
      <collision>
        <origin xyz="0 0 0" rpy="${M_PI/2} 0 0"/>
        <geometry>
          <mesh filename="${mesh}" scale="${wheel_scale}"/>
        </geometry>
      </collision>
      <xacro:inertial_cylinder mass="1.5" radius="0.15" length="0.1"/>
    </link>

    <joint name="${name}_joint" type="continuous">
      <parent link="${parent}"/>
      <child link="${name}_link"/>
      <origin xyz="${xyz}" rpy="0 0 0"/>
      <axis xyz="0 1 0"/>
      <dynamics damping="0.05"/>
    </joint>
  </xacro:macro>

</robot>